<?xml version="1.0" encoding="utf-8"?>
<!-- This URDF was automatically created by SolidWorks to URDF Exporter! Originally created by Stephen Brawner (brawner@gmail.com) 
     Commit Version: 1.6.0-4-g7f85cfe  Build Version: 1.6.7995.38578
     For more information, please see http://wiki.ros.org/sw_urdf_exporter -->
<robot
  name="r1urdfv20">
  <link
    name="base_link">
    <inertial>
      <origin
        xyz="-0.026382 -0.0012728 0.5966"
        rpy="0 0 0" />
      <mass
        value="15.491" />
      <inertia
        ixx="0.13933"
        ixy="-3.1833E-06"
        ixz="-7.9787E-05"
        iyy="0.090681"
        iyz="-1.7144E-05"
        izz="0.074444" />
    </inertial>
    <visual>
      <origin
        xyz="0 0 0"
        rpy="0 0 0" />
      <geometry>
        <mesh
          filename="package://r1urdfv20/meshes/base_link.STL" />
      </geometry>
      <material
        name="">
        <color
          rgba="0.6 0.6 0.6 1" />
      </material>
    </visual>
    <collision>
      <origin
        xyz="0 0 0"
        rpy="0 0 0" />
      <geometry>
        <mesh
          filename="package://r1urdfv20/meshes/base_link.STL" />
      </geometry>
    </collision>
  </link>
  <link
    name="right_arm_1_Link">
    <inertial>
      <origin
        xyz="0.00048295 0.066513 -4.391E-05"
        rpy="0 0 0" />
      <mass
        value="0.3988" />
      <inertia
        ixx="0.00047196"
        ixy="2.0689E-07"
        ixz="-1.1491E-08"
        iyy="0.00029232"
        iyz="3.8468E-09"
        izz="0.00029753" />
    </inertial>
    <visual>
      <origin
        xyz="0 0 0"
        rpy="0 0 0" />
      <geometry>
        <mesh
          filename="package://r1urdfv20/meshes/right_arm_1_Link.STL" />
      </geometry>
      <material
        name="">
        <color
          rgba="0.86275 0.93333 0.92941 1" />
      </material>
    </visual>
    <collision>
      <origin
        xyz="0 0 0"
        rpy="0 0 0" />
      <geometry>
        <mesh
          filename="package://r1urdfv20/meshes/right_arm_1_Link.STL" />
      </geometry>
    </collision>
  </link>
  <joint
    name="right_arm_1"
    type="revolute">
    <origin
      xyz="-0.055 -0.1293 1.375"
      rpy="3.1416 1.5708 0" />
    <parent
      link="base_link" />
    <child
      link="right_arm_1_Link" />
    <axis
      xyz="0 1 0" />
    <limit
      lower="-2.9671"
      upper="2.9671"
      effort="40"
      velocity="20.944" />
  </joint>
  <link
    name="right_arm_2_Link">
    <inertial>
      <origin
        xyz="0.242 0.032943 -0.021091"
        rpy="0 0 0" />
      <mass
        value="0.3043" />
      <inertia
        ixx="8.211E-05"
        ixy="-8.0136E-07"
        ixz="7.5433E-06"
        iyy="0.0004609"
        iyz="3.4645E-07"
        izz="0.00043677" />
    </inertial>
    <visual>
      <origin
        xyz="0 0 0"
        rpy="0 0 0" />
      <geometry>
        <mesh
          filename="package://r1urdfv20/meshes/right_arm_2_Link.STL" />
      </geometry>
      <material
        name="">
        <color
          rgba="0.86275 0.93333 0.92941 1" />
      </material>
    </visual>
    <collision>
      <origin
        xyz="0 0 0"
        rpy="0 0 0" />
      <geometry>
        <mesh
          filename="package://r1urdfv20/meshes/right_arm_2_Link.STL" />
      </geometry>
    </collision>
  </link>
  <joint
    name="right_arm_2"
    type="revolute">
    <origin
      xyz="0.0316 0.0682 0"
      rpy="1.5708 -1.5708 0" />
    <parent
      link="right_arm_1_Link" />
    <child
      link="right_arm_2_Link" />
    <axis
      xyz="0 1 0" />
    <limit
      lower="0"
      upper="3.1416"
      effort="40"
      velocity="20.944" />
  </joint>
  <link
    name="right_arm_3_Link">
    <inertial>
      <origin
        xyz="0.056289 0.028703 0.046011"
        rpy="0 0 0" />
      <mass
        value="0.17673" />
      <inertia
        ixx="7.1112E-05"
        ixy="7.7555E-08"
        ixz="-1.3314E-05"
        iyy="7.316E-05"
        iyz="1.5614E-07"
        izz="7.8276E-05" />
    </inertial>
    <visual>
      <origin
        xyz="0 0 0"
        rpy="0 0 0" />
      <geometry>
        <mesh
          filename="package://r1urdfv20/meshes/right_arm_3_Link.STL" />
      </geometry>
      <material
        name="">
        <color
          rgba="0.86275 0.93333 0.92941 1" />
      </material>
    </visual>
    <collision>
      <origin
        xyz="0 0 0"
        rpy="0 0 0" />
      <geometry>
        <mesh
          filename="package://r1urdfv20/meshes/right_arm_3_Link.STL" />
      </geometry>
    </collision>
  </link>
  <joint
    name="right_arm_3"
    type="revolute">
    <origin
      xyz="0.3493 0.0602 -0.02"
      rpy="0 1.6424 3.1416" />
    <parent
      link="right_arm_2_Link" />
    <child
      link="right_arm_3_Link" />
    <axis
      xyz="0 -1 0" />
    <limit
      lower="-3.2289"
      upper="0"
      effort="27"
      velocity="7.5398" />
  </joint>
  <link
    name="right_arm_4_Link">
    <inertial>
      <origin
        xyz="-0.00011589 -0.00095341 0.1625"
        rpy="0 0 0" />
      <mass
        value="0.1739" />
      <inertia
        ixx="9.6664E-05"
        ixy="-1.1432E-08"
        ixz="2.2087E-08"
        iyy="0.00010742"
        iyz="8.1899E-08"
        izz="4.3082E-05" />
    </inertial>
    <visual>
      <origin
        xyz="0 0 0"
        rpy="0 0 0" />
      <geometry>
        <mesh
          filename="package://r1urdfv20/meshes/right_arm_4_Link.STL" />
      </geometry>
      <material
        name="">
        <color
          rgba="0.80784 0.84314 0.90588 1" />
      </material>
    </visual>
    <collision>
      <origin
        xyz="0 0 0"
        rpy="0 0 0" />
      <geometry>
        <mesh
          filename="package://r1urdfv20/meshes/right_arm_4_Link.STL" />
      </geometry>
    </collision>
  </link>
  <joint
    name="right_arm_4"
    type="revolute">
    <origin
      xyz="0.064765 0.0286 0.075477"
      rpy="-0.071618 0 1.5708" />
    <parent
      link="right_arm_3_Link" />
    <child
      link="right_arm_4_Link" />
    <axis
      xyz="0 0 1" />
    <limit
      lower="-2.9671"
      upper="2.9671"
      effort="7"
      velocity="25.133" />
  </joint>
  <link
    name="right_arm_5_Link">
    <inertial>
      <origin
        xyz="0.053183 7.0332E-05 -0.015834"
        rpy="0 0 0" />
      <mass
        value="0.12576" />
      <inertia
        ixx="4.7409E-05"
        ixy="-1.1419E-08"
        ixz="-1.355E-07"
        iyy="3.8455E-05"
        iyz="2.2091E-08"
        izz="4.0187E-05" />
    </inertial>
    <visual>
      <origin
        xyz="0 0 0"
        rpy="0 0 0" />
      <geometry>
        <mesh
          filename="package://r1urdfv20/meshes/right_arm_5_Link.STL" />
      </geometry>
      <material
        name="">
        <color
          rgba="0.80784 0.84314 0.90588 1" />
      </material>
    </visual>
    <collision>
      <origin
        xyz="0 0 0"
        rpy="0 0 0" />
      <geometry>
        <mesh
          filename="package://r1urdfv20/meshes/right_arm_5_Link.STL" />
      </geometry>
    </collision>
  </link>
  <joint
    name="right_arm_5"
    type="revolute">
    <origin
      xyz="0 -0.019 0.203"
      rpy="1.5708 -1.5708 0" />
    <parent
      link="right_arm_4_Link" />
    <child
      link="right_arm_5_Link" />
    <axis
      xyz="0 0 1" />
    <limit
      lower="-1.5708"
      upper="1.5708"
      effort="7"
      velocity="25.133" />
  </joint>
  <link
    name="right_arm_6_Link">
    <inertial>
      <origin
        xyz="9.006E-05 -0.015875 1.5779E-05"
        rpy="0 0 0" />
      <mass
        value="0.12251" />
      <inertia
        ixx="3.7405E-05"
        ixy="-1.1418E-08"
        ixz="-2.2072E-08"
        iyy="5.199E-05"
        iyz="-2.2628E-12"
        izz="3.9632E-05" />
    </inertial>
    <visual>
      <origin
        xyz="0 0 0"
        rpy="0 0 0" />
      <geometry>
        <mesh
          filename="package://r1urdfv20/meshes/right_arm_6_Link.STL" />
      </geometry>
      <material
        name="">
        <color
          rgba="0.80784 0.84314 0.90588 1" />
      </material>
    </visual>
    <collision>
      <origin
        xyz="0 0 0"
        rpy="0 0 0" />
      <geometry>
        <mesh
          filename="package://r1urdfv20/meshes/right_arm_6_Link.STL" />
      </geometry>
    </collision>
  </link>
  <joint
    name="right_arm_6"
    type="revolute">
    <origin
      xyz="0.127 0 -0.019"
      rpy="0 0 -1.5708" />
    <parent
      link="right_arm_5_Link" />
    <child
      link="right_arm_6_Link" />
    <axis
      xyz="0 1 0" />
    <limit
      lower="-3.1416"
      upper="3.1416"
      effort="7"
      velocity="25.133" />
  </joint>
  <link
    name="right_gripper_1_Link">
    <inertial>
      <origin
        xyz="0.0151 0.046663 0.0013002"
        rpy="0 0 0" />
      <mass
        value="0.02084" />
      <inertia
        ixx="5.3593E-06"
        ixy="3.2105E-07"
        ixz="8.4132E-08"
        iyy="1.6486E-06"
        iyz="8.4389E-08"
        izz="4.7101E-06" />
    </inertial>
    <visual>
      <origin
        xyz="0 0 0"
        rpy="0 0 0" />
      <geometry>
        <mesh
          filename="package://r1urdfv20/meshes/right_gripper_1_Link.STL" />
      </geometry>
      <material
        name="">
        <color
          rgba="0.80784 0.84314 0.90588 1" />
      </material>
    </visual>
    <collision>
      <origin
        xyz="0 0 0"
        rpy="0 0 0" />
      <geometry>
        <mesh
          filename="package://r1urdfv20/meshes/right_gripper_1_Link.STL" />
      </geometry>
    </collision>
  </link>
  <joint
    name="right_gripper_1"
    type="prismatic">
    <origin
      xyz="0 0 0"
      rpy="0 0 0" />
    <parent
      link="right_arm_6_Link" />
    <child
      link="right_gripper_1_Link" />
    <axis
      xyz="1 0 0" />
    <limit
      lower="-0.01139"
      upper="0.01861"
      effort="200"
      velocity="0.25" />
  </joint>
  <link
    name="right_gripper_2_Link">
    <inertial>
      <origin
        xyz="-0.0151 0.046663 -0.0013002"
        rpy="0 0 0" />
      <mass
        value="0.02084" />
      <inertia
        ixx="5.3593E-06"
        ixy="-3.2105E-07"
        ixz="8.4132E-08"
        iyy="1.6486E-06"
        iyz="-8.439E-08"
        izz="4.7101E-06" />
    </inertial>
    <visual>
      <origin
        xyz="0 0 0"
        rpy="0 0 0" />
      <geometry>
        <mesh
          filename="package://r1urdfv20/meshes/right_gripper_2_Link.STL" />
      </geometry>
      <material
        name="">
        <color
          rgba="0.75294 0.75294 0.75294 1" />
      </material>
    </visual>
    <collision>
      <origin
        xyz="0 0 0"
        rpy="0 0 0" />
      <geometry>
        <mesh
          filename="package://r1urdfv20/meshes/right_gripper_2_Link.STL" />
      </geometry>
    </collision>
  </link>
  <joint
    name="right_gripper_2"
    type="prismatic">
    <origin
      xyz="0 0 0"
      rpy="0 0 0" />
    <parent
      link="right_arm_6_Link" />
    <child
      link="right_gripper_2_Link" />
    <axis
      xyz="-1 0 0" />
    <limit
      lower="-0.01139"
      upper="0.01861"
      effort="200"
      velocity="0.25" />
  </joint>
  <link
    name="left_arm_1_Link">
    <inertial>
      <origin
        xyz="0.00048295 -0.066513 4.391E-05"
        rpy="0 0 0" />
      <mass
        value="0.3988" />
      <inertia
        ixx="0.00047196"
        ixy="-2.0689E-07"
        ixz="1.1491E-08"
        iyy="0.00029232"
        iyz="3.8468E-09"
        izz="0.00029753" />
    </inertial>
    <visual>
      <origin
        xyz="0 0 0"
        rpy="0 0 0" />
      <geometry>
        <mesh
          filename="package://r1urdfv20/meshes/left_arm_1_Link.STL" />
      </geometry>
      <material
        name="">
        <color
          rgba="0.86275 0.93333 0.92941 1" />
      </material>
    </visual>
    <collision>
      <origin
        xyz="0 0 0"
        rpy="0 0 0" />
      <geometry>
        <mesh
          filename="package://r1urdfv20/meshes/left_arm_1_Link.STL" />
      </geometry>
    </collision>
  </link>
  <joint
    name="left_arm_1"
    type="revolute">
    <origin
      xyz="-0.055 0.1293 1.375"
      rpy="0 -1.5708 3.14159265358979" />
    <parent
      link="base_link" />
    <child
      link="left_arm_1_Link" />
    <axis
      xyz="0 -1 0" />
    <limit
      lower="-2.9671"
      upper="2.9671"
      effort="40"
      velocity="20.944" />
  </joint>
  <link
    name="left_arm_2_Link">
    <inertial>
      <origin
        xyz="0.242 0.032943 -0.021091"
        rpy="0 0 0" />
      <mass
        value="0.3043" />
      <inertia
        ixx="8.211E-05"
        ixy="-8.0136E-07"
        ixz="7.5433E-06"
        iyy="0.0004609"
        iyz="3.4645E-07"
        izz="0.00043677" />
    </inertial>
    <visual>
      <origin
        xyz="0 0 0"
        rpy="0 0 0" />
      <geometry>
        <mesh
          filename="package://r1urdfv20/meshes/left_arm_2_Link.STL" />
      </geometry>
      <material
        name="">
        <color
          rgba="0.86275 0.93333 0.92941 1" />
      </material>
    </visual>
    <collision>
      <origin
        xyz="0 0 0"
        rpy="0 0 0" />
      <geometry>
        <mesh
          filename="package://r1urdfv20/meshes/left_arm_2_Link.STL" />
      </geometry>
    </collision>
  </link>
  <joint
    name="left_arm_2"
    type="revolute">
    <origin
      xyz="0.0316 -0.0682 0"
      rpy="-1.5708 1.5708 0" />
    <parent
      link="left_arm_1_Link" />
    <child
      link="left_arm_2_Link" />
    <axis
      xyz="0 1 0" />
    <limit
      lower="0"
      upper="3.1416"
      effort="40"
      velocity="20.944" />
  </joint>
  <link
    name="left_arm_3_Link">
    <inertial>
      <origin
        xyz="0.056289 0.028703 0.046011"
        rpy="0 0 0" />
      <mass
        value="0.17673" />
      <inertia
        ixx="7.1112E-05"
        ixy="7.755E-08"
        ixz="-1.3314E-05"
        iyy="7.316E-05"
        iyz="1.5613E-07"
        izz="7.8276E-05" />
    </inertial>
    <visual>
      <origin
        xyz="0 0 0"
        rpy="0 0 0" />
      <geometry>
        <mesh
          filename="package://r1urdfv20/meshes/left_arm_3_Link.STL" />
      </geometry>
      <material
        name="">
        <color
          rgba="0.86275 0.93333 0.92941 1" />
      </material>
    </visual>
    <collision>
      <origin
        xyz="0 0 0"
        rpy="0 0 0" />
      <geometry>
        <mesh
          filename="package://r1urdfv20/meshes/left_arm_3_Link.STL" />
      </geometry>
    </collision>
  </link>
  <joint
    name="left_arm_3"
    type="revolute">
    <origin
      xyz="0.3493 0.0602 -0.02"
      rpy="0 1.6424 3.1416" />
    <parent
      link="left_arm_2_Link" />
    <child
      link="left_arm_3_Link" />
    <axis
      xyz="0 -1 0" />
    <limit
      lower="-3.2289"
      upper="0"
      effort="27"
      velocity="7.5398" />
  </joint>
  <link
    name="left_arm_4_Link">
    <inertial>
      <origin
        xyz="0.00011589 0.00095341 0.1725"
        rpy="0 0 0" />
      <mass
        value="0.1739" />
      <inertia
        ixx="9.6664E-05"
        ixy="-1.1432E-08"
        ixz="-2.2087E-08"
        iyy="0.00010742"
        iyz="-8.1899E-08"
        izz="4.3082E-05" />
    </inertial>
    <visual>
      <origin
        xyz="0 0 0"
        rpy="0 0 0" />
      <geometry>
        <mesh
          filename="package://r1urdfv20/meshes/left_arm_4_Link.STL" />
      </geometry>
      <material
        name="">
        <color
          rgba="0.80784 0.84314 0.90588 1" />
      </material>
    </visual>
    <collision>
      <origin
        xyz="0 0 0"
        rpy="0 0 0" />
      <geometry>
        <mesh
          filename="package://r1urdfv20/meshes/left_arm_4_Link.STL" />
      </geometry>
    </collision>
  </link>
  <joint
    name="left_arm_4"
    type="revolute">
    <origin
      xyz="0.065481 0.0286 0.065502"
      rpy="0.071618 0 -1.5708" />
    <parent
      link="left_arm_3_Link" />
    <child
      link="left_arm_4_Link" />
    <axis
      xyz="0 0 1" />
    <limit
      lower="-2.9671"
      upper="2.9671"
      effort="7"
      velocity="25.133" />
  </joint>
  <link
    name="left_arm_5_Link">
    <inertial>
      <origin
        xyz="0.053183 7.0332E-05 -0.015834"
        rpy="0 0 0" />
      <mass
        value="0.12576" />
      <inertia
        ixx="4.7409E-05"
        ixy="-1.1419E-08"
        ixz="-1.355E-07"
        iyy="3.8455E-05"
        iyz="2.2091E-08"
        izz="4.0187E-05" />
    </inertial>
    <visual>
      <origin
        xyz="0 0 0"
        rpy="0 0 0" />
      <geometry>
        <mesh
          filename="package://r1urdfv20/meshes/left_arm_5_Link.STL" />
      </geometry>
      <material
        name="">
        <color
          rgba="0.80784 0.84314 0.90588 1" />
      </material>
    </visual>
    <collision>
      <origin
        xyz="0 0 0"
        rpy="0 0 0" />
      <geometry>
        <mesh
          filename="package://r1urdfv20/meshes/left_arm_5_Link.STL" />
      </geometry>
    </collision>
  </link>
  <joint
    name="left_arm_5"
    type="revolute">
    <origin
      xyz="0 0.019 0.213"
      rpy="1.5708 -1.5708 3.1416" />
    <parent
      link="left_arm_4_Link" />
    <child
      link="left_arm_5_Link" />
    <axis
      xyz="0 0 1" />
    <limit
      lower="-1.5708"
      upper="1.5708"
      effort="7"
      velocity="25.133" />
  </joint>
  <link
    name="left_arm_6_Link">
    <inertial>
      <origin
        xyz="9.006E-05 0.015875 -1.5779E-05"
        rpy="0 0 0" />
      <mass
        value="0.12251" />
      <inertia
        ixx="3.7405E-05"
        ixy="1.1418E-08"
        ixz="2.2072E-08"
        iyy="5.199E-05"
        iyz="-2.2628E-12"
        izz="3.9632E-05" />
    </inertial>
    <visual>
      <origin
        xyz="0 0 0"
        rpy="0 0 0" />
      <geometry>
        <mesh
          filename="package://r1urdfv20/meshes/left_arm_6_Link.STL" />
      </geometry>
      <material
        name="">
        <color
          rgba="0.80784 0.84314 0.90588 1" />
      </material>
    </visual>
    <collision>
      <origin
        xyz="0 0 0"
        rpy="0 0 0" />
      <geometry>
        <mesh
          filename="package://r1urdfv20/meshes/left_arm_6_Link.STL" />
      </geometry>
    </collision>
  </link>
  <joint
    name="left_arm_6"
    type="revolute">
    <origin
      xyz="0.127 0 -0.019"
      rpy="-3.1416 0 -1.5708" />
    <parent
      link="left_arm_5_Link" />
    <child
      link="left_arm_6_Link" />
    <axis
      xyz="0 -1 0" />
    <limit
      lower="-1.5708"
      upper="1.5708"
      effort="7"
      velocity="25.133" />
  </joint>
  <link
    name="left_gripper_1_Link">
    <inertial>
      <origin
        xyz="0.0151 -0.046663 -0.0013002"
        rpy="0 0 0" />
      <mass
        value="0.02084" />
      <inertia
        ixx="5.3593E-06"
        ixy="-3.2105E-07"
        ixz="-8.4132E-08"
        iyy="1.6486E-06"
        iyz="8.4389E-08"
        izz="4.7101E-06" />
    </inertial>
    <visual>
      <origin
        xyz="0 0 0"
        rpy="0 0 0" />
      <geometry>
        <mesh
          filename="package://r1urdfv20/meshes/left_gripper_1_Link.STL" />
      </geometry>
      <material
        name="">
        <color
          rgba="0.80784 0.84314 0.90588 1" />
      </material>
    </visual>
    <collision>
      <origin
        xyz="0 0 0"
        rpy="0 0 0" />
      <geometry>
        <mesh
          filename="package://r1urdfv20/meshes/left_gripper_1_Link.STL" />
      </geometry>
    </collision>
  </link>
  <joint
    name="left_gripper_1"
    type="prismatic">
    <origin
      xyz="0 0 0"
      rpy="0 0 0" />
    <parent
      link="left_arm_6_Link" />
    <child
      link="left_gripper_1_Link" />
    <axis
      xyz="1 0 0" />
    <limit
      lower="-0.01139"
      upper="0.01861"
      effort="200"
      velocity="0.25" />
  </joint>
  <link
    name="left_gripper_2_Link">
    <inertial>
      <origin
        xyz="-0.0151 -0.046663 0.0013002"
        rpy="0 0 0" />
      <mass
        value="0.02084" />
      <inertia
        ixx="5.3593E-06"
        ixy="3.2105E-07"
        ixz="-8.4132E-08"
        iyy="1.6486E-06"
        iyz="-8.439E-08"
        izz="4.7101E-06" />
    </inertial>
    <visual>
      <origin
        xyz="0 0 0"
        rpy="0 0 0" />
      <geometry>
        <mesh
          filename="package://r1urdfv20/meshes/left_gripper_2_Link.STL" />
      </geometry>
      <material
        name="">
        <color
          rgba="0.71765 0.80784 0.76471 1" />
      </material>
    </visual>
    <collision>
      <origin
        xyz="0 0 0"
        rpy="0 0 0" />
      <geometry>
        <mesh
          filename="package://r1urdfv20/meshes/left_gripper_2_Link.STL" />
      </geometry>
    </collision>
  </link>
  <joint
    name="left_gripper_2"
    type="prismatic">
    <origin
      xyz="0 0 0"
      rpy="0 0 0" />
    <parent
      link="left_arm_6_Link" />
    <child
      link="left_gripper_2_Link" />
    <axis
      xyz="-1 0 0" />
    <limit
      lower="-0.01139"
      upper="0.01861"
      effort="200"
      velocity="0.25" />
  </joint>
  <link
    name="front_right_turn_Link">
    <inertial>
      <origin
        xyz="-0.012414 0.032699 -0.046417"
        rpy="0 0 0" />
      <mass
        value="0.16675" />
      <inertia
        ixx="7.3159E-05"
        ixy="3.7819E-06"
        ixz="3.7917E-06"
        iyy="9.3643E-05"
        iyz="-4.3522E-07"
        izz="0.00011402" />
    </inertial>
    <visual>
      <origin
        xyz="0 0 0"
        rpy="0 0 0" />
      <geometry>
        <mesh
          filename="package://r1urdfv20/meshes/front_right_turn_Link.STL" />
      </geometry>
      <material
        name="">
        <color
          rgba="1 1 1 1" />
      </material>
    </visual>
    <collision>
      <origin
        xyz="0 0 0"
        rpy="0 0 0" />
      <geometry>
        <mesh
          filename="package://r1urdfv20/meshes/front_right_turn_Link.STL" />
      </geometry>
    </collision>
  </link>
  <joint
    name="front_right_turn"
    type="revolute">
    <origin
      xyz="0.134 -0.19 0.093"
      rpy="0 0 0" />
    <parent
      link="base_link" />
    <child
      link="front_right_turn_Link" />
    <axis
      xyz="0 0 1" />
    <limit
      lower="-1.5708"
      upper="1.5708"
      effort="30"
      velocity="3.1416" />
  </joint>
  <link
    name="front_right_wheel_Link">
    <inertial>
      <origin
        xyz="-0.012646 4.103E-08 1.2733E-07"
        rpy="0 0 0" />
      <mass
        value="0.50128" />
      <inertia
        ixx="0.001126"
        ixy="-7.075E-12"
        ixz="-5.024E-10"
        iyy="0.00060866"
        iyz="4.3853E-10"
        izz="0.00060864" />
    </inertial>
    <visual>
      <origin
        xyz="0 0 0"
        rpy="0 0 0" />
      <geometry>
        <mesh
          filename="package://r1urdfv20/meshes/front_right_wheel_Link.STL" />
      </geometry>
      <material
        name="">
        <color
          rgba="0.59216 0.66667 0.68235 1" />
      </material>
    </visual>
    <collision>
      <origin
        xyz="0 0 0"
        rpy="0 0 0" />
      <geometry>
        <mesh
          filename="package://r1urdfv20/meshes/front_right_wheel_Link.STL" />
      </geometry>
    </collision>
  </link>
  <joint
    name="front_right_wheel"
    type="continuous">
    <origin
      xyz="0.00093535 0.01445 -0.098784"
      rpy="1.6618 0 1.5708" />
    <parent
      link="front_right_turn_Link" />
    <child
      link="front_right_wheel_Link" />
    <axis
      xyz="1 0 0" />
    <limit
      lower="-31416"
      upper="31416"
      effort="3.2"
      velocity="14.389" />
  </joint>
  <link
    name="rear_turn_Link">
    <inertial>
      <origin
        xyz="0.010502 -0.033391 -0.045748"
        rpy="0 0 0" />
      <mass
        value="0.16929" />
      <inertia
        ixx="7.5887E-05"
        ixy="5.053E-06"
        ixz="-3.7803E-06"
        iyy="9.6739E-05"
        iyz="4.7274E-07"
        izz="0.0001198" />
    </inertial>
    <visual>
      <origin
        xyz="0 0 0"
        rpy="0 0 0" />
      <geometry>
        <mesh
          filename="package://r1urdfv20/meshes/rear_turn_Link.STL" />
      </geometry>
      <material
        name="">
        <color
          rgba="1 1 1 1" />
      </material>
    </visual>
    <collision>
      <origin
        xyz="0 0 0"
        rpy="0 0 0" />
      <geometry>
        <mesh
          filename="package://r1urdfv20/meshes/rear_turn_Link.STL" />
      </geometry>
    </collision>
  </link>
  <joint
    name="rear_turn"
    type="revolute">
    <origin
      xyz="-0.145 0 0.093"
      rpy="0 0 0" />
    <parent
      link="base_link" />
    <child
      link="rear_turn_Link" />
    <axis
      xyz="0 0 1" />
    <limit
      lower="-1.5708"
      upper="1.5708"
      effort="30"
      velocity="3.1416" />
  </joint>
  <link
    name="rear_wheel_Link">
    <inertial>
      <origin
        xyz="-0.012646 4.103E-08 1.2733E-07"
        rpy="0 0 0" />
      <mass
        value="0.50128" />
      <inertia
        ixx="0.001126"
        ixy="-7.075E-12"
        ixz="-5.024E-10"
        iyy="0.00060866"
        iyz="4.3853E-10"
        izz="0.00060864" />
    </inertial>
    <visual>
      <origin
        xyz="0 0 0"
        rpy="0 0 0" />
      <geometry>
        <mesh
          filename="package://r1urdfv20/meshes/rear_wheel_Link.STL" />
      </geometry>
      <material
        name="">
        <color
          rgba="0.59216 0.66667 0.68235 1" />
      </material>
    </visual>
    <collision>
      <origin
        xyz="0 0 0"
        rpy="0 0 0" />
      <geometry>
        <mesh
          filename="package://r1urdfv20/meshes/rear_wheel_Link.STL" />
      </geometry>
    </collision>
  </link>
  <joint
    name="rear_wheel"
    type="continuous">
    <origin
      xyz="-0.00093535 -0.01445 -0.098784"
      rpy="1.6618 0 -1.5708" />
    <parent
      link="rear_turn_Link" />
    <child
      link="rear_wheel_Link" />
    <axis
      xyz="-1 0 0" />
    <limit
      lower="-31416"
      upper="31416"
      effort="3.2"
      velocity="14.389" />
  </joint>
  <link
    name="front_left_turn_Link">
    <inertial>
      <origin
        xyz="-0.01239 -0.032748 -0.046377"
        rpy="0 0 0" />
      <mass
        value="0.16689" />
      <inertia
        ixx="7.3217E-05"
        ixy="-3.8098E-06"
        ixz="3.7915E-06"
        iyy="9.3648E-05"
        iyz="-4.4278E-07"
        izz="0.00011408" />
    </inertial>
    <visual>
      <origin
        xyz="0 0 0"
        rpy="0 0 0" />
      <geometry>
        <mesh
          filename="package://r1urdfv20/meshes/front_left_turn_Link.STL" />
      </geometry>
      <material
        name="">
        <color
          rgba="1 1 1 1" />
      </material>
    </visual>
    <collision>
      <origin
        xyz="0 0 0"
        rpy="0 0 0" />
      <geometry>
        <mesh
          filename="package://r1urdfv20/meshes/front_left_turn_Link.STL" />
      </geometry>
    </collision>
  </link>
  <joint
    name="front_left_turn"
    type="revolute">
    <origin
      xyz="0.134 0.19 0.093"
      rpy="0 0 0" />
    <parent
      link="base_link" />
    <child
      link="front_left_turn_Link" />
    <axis
      xyz="0 0 1" />
    <limit
      lower="-1.5708"
      upper="1.5708"
      effort="30"
      velocity="3.1416" />
  </joint>
  <link
    name="front_left_wheel_Link">
    <inertial>
      <origin
        xyz="-0.012646 4.103E-08 1.2733E-07"
        rpy="0 0 0" />
      <mass
        value="0.50128" />
      <inertia
        ixx="0.001126"
        ixy="-7.0758E-12"
        ixz="-5.024E-10"
        iyy="0.00060866"
        iyz="1.9226E-09"
        izz="0.00060863" />
    </inertial>
    <visual>
      <origin
        xyz="0 0 0"
        rpy="0 0 0" />
      <geometry>
        <mesh
          filename="package://r1urdfv20/meshes/front_left_wheel_Link.STL" />
      </geometry>
      <material
        name="">
        <color
          rgba="0.59216 0.66667 0.68235 1" />
      </material>
    </visual>
    <collision>
      <origin
        xyz="0 0 0"
        rpy="0 0 0" />
      <geometry>
        <mesh
          filename="package://r1urdfv20/meshes/front_left_wheel_Link.STL" />
      </geometry>
    </collision>
  </link>
  <joint
    name="front_left_wheel"
    type="continuous">
    <origin
      xyz="0.00093535 -0.01445 -0.098784"
      rpy="1.4605 0 -1.5708" />
    <parent
      link="front_left_turn_Link" />
    <child
      link="front_left_wheel_Link" />
    <axis
      xyz="-1 0 0" />
    <limit
      lower="-31416"
      upper="31416"
      effort="3.2"
      velocity="14.389" />
  </joint>
  <link
    name="realsensecamera_link">
    <inertial>
      <origin
        xyz="0 0 0"
        rpy="0 0 0" />
      <mass
        value="0" />
      <inertia
        ixx="0"
        ixy="0"
        ixz="0"
        iyy="0"
        iyz="0"
        izz="0" />
    </inertial>
    <visual>
      <origin
        xyz="0 0 0"
        rpy="0 0 0" />
      <geometry>
        <mesh
          filename="package://r1urdfv20/meshes/realsensecamera_link.STL" />
      </geometry>
      <material
        name="">
        <color
          rgba="1 1 1 1" />
      </material>
    </visual>
    <collision>
      <origin
        xyz="0 0 0"
        rpy="0 0 0" />
      <geometry>
        <mesh
          filename="package://r1urdfv20/meshes/realsensecamera_link.STL" />
      </geometry>
    </collision>
  </link>
  <joint
    name="realsensecamera_joint"
    type="fixed">
    <origin
      xyz="-0.053794 0 1.4848"
      rpy="2.0071 0 1.5708" />
    <parent
      link="base_link" />
    <child
      link="realsensecamera_link" />
    <axis
      xyz="0 0 0" />
  </joint>
</robot>
