<?xml version="1.0" encoding="utf-8"?>
<!-- This URDF was automatically created by SolidWorks to URDF Exporter! Originally created by Stephen Brawner (brawner@gmail.com) 
     Commit Version: 1.6.0-4-g7f85cfe  Build Version: 1.6.7995.38578
     For more information, please see http://wiki.ros.org/sw_urdf_exporter -->
<robot
  name="a1_arm_v3">
  <link
    name="arm_base_link">
    <inertial>
      <origin
        xyz="-5.0929E-05 -1.2945E-05 -0.017332"
        rpy="0 0 0" />
      <mass
        value="1.00" />
      <inertia
        ixx="0.00028666"
        ixy="-1.5892E-07"
        ixz="1.4172E-08"
        iyy="0.00028649"
        iyz="5.0884E-09"
        izz="0.00045899" />
    </inertial>
    <visual>
      <origin
        xyz="0 0 0"
        rpy="0 0 0" />
      <geometry>
        <mesh
          filename="package://a1_arm_v3/meshes/arm_base_link.STL" />
      </geometry>
      <material
        name="">
        <color
          rgba="0.75294 0.75294 0.75294 1" />
      </material>
    </visual>
    <collision>
      <origin
        xyz="0 0 0"
        rpy="0 0 0" />
      <geometry>
        <mesh
          filename="package://a1_arm_v3/meshes/arm_base_link.STL" />
      </geometry>
    </collision>
  </link>
  <link
    name="arm_seg1">
    <inertial>
      <origin
        xyz="0.0008545 -3.0801E-05 0.063737"
        rpy="0 0 0" />
      <mass
        value="1.322" />
      <inertia
        ixx="0.00056364"
        ixy="1.1493E-08"
        ixz="-9.7293E-09"
        iyy="0.00035434"
        iyz="3.8164E-09"
        izz="0.00033273" />
    </inertial>
    <visual>
      <origin
        xyz="0 0 0"
        rpy="0 0 0" />
      <geometry>
        <mesh
          filename="package://a1_arm_v3/meshes/arm_seg1.STL" />
      </geometry>
      <material
        name="">
        <color
          rgba="0.89804 0.91765 0.92941 1" />
      </material>
    </visual>
    <collision>
      <origin
        xyz="0 0 0"
        rpy="0 0 0" />
      <geometry>
        <mesh
          filename="package://a1_arm_v3/meshes/arm_seg1.STL" />
      </geometry>
    </collision>
  </link>
  <joint
    name="arm_joint1"
    type="revolute">
    <limit effort="87" lower="-3.14" upper="3.14" velocity="2" />
    <origin
      xyz="0 0 0"
      rpy="0 0 1.5708" />
    <parent
      link="arm_base_link" />
    <child
      link="arm_seg1" />
    <axis
      xyz="0 0 1" />
  </joint>
  <link
    name="arm_seg2">
    <inertial>
      <origin
        xyz="-0.038073 0.20611 0.021318"
        rpy="0 0 0" />
      <mass
        value="1.004" />
      <inertia
        ixx="0.0011899"
        ixy="-1.9281E-06"
        ixz="-9.3286E-07"
        iyy="0.00014197"
        iyz="-1.9731E-05"
        izz="0.0011288" />
    </inertial>
    <visual>
      <origin
        xyz="0 0 0"
        rpy="0 0 0" />
      <geometry>
        <mesh
          filename="package://a1_arm_v3/meshes/arm_seg2.STL" />
      </geometry>
      <material
        name="">
        <color
          rgba="0.89804 0.91765 0.92941 1" />
      </material>
    </visual>
    <collision>
      <origin
        xyz="0 0 0"
        rpy="0 0 0" />
      <geometry>
        <mesh
          filename="package://a1_arm_v3/meshes/arm_seg2.STL" />
      </geometry>
    </collision>
  </link>
  <joint
    name="arm_joint2"
    type="revolute">
    <limit effort="87" lower="-0.75" upper="3.14" velocity="2" />
    <origin
      xyz="0.0376 0 0.0682"
      rpy="0 0 0" />
    <parent
      link="arm_seg1" />
    <child
      link="arm_seg2" />
    <axis
      xyz="1 0 0" />
  </joint>
  <link
    name="arm_seg3">
    <inertial>
      <origin
        xyz="-0.028331 -0.042749 0.053055"
        rpy="0 0 0" />
      <mass
        value="0.55" />
      <inertia
        ixx="0.00014357"
        ixy="3.8639E-07"
        ixz="-2.7558E-07"
        iyy="0.00014734"
        iyz="3.5243E-05"
        izz="0.00013264" />
    </inertial>
    <visual>
      <origin
        xyz="0 0 0"
        rpy="0 0 0" />
      <geometry>
        <mesh
          filename="package://a1_arm_v3/meshes/arm_seg3.STL" />
      </geometry>
      <material
        name="">
        <color
          rgba="0.89804 0.91765 0.92941 1" />
      </material>
    </visual>
    <collision>
      <origin
        xyz="0 0 0"
        rpy="0 0 0" />
      <geometry>
        <mesh
          filename="package://a1_arm_v3/meshes/arm_seg3.STL" />
      </geometry>
    </collision>
  </link>
  <joint
    name="arm_joint3"
    type="revolute">
    <limit effort="87" lower="-3.14" upper="0" velocity="2" />
    <origin
      xyz="-0.009 0.3493 0.02"
      rpy="0 0 0" />
    <parent
      link="arm_seg2" />
    <child
      link="arm_seg3" />
    <axis
      xyz="1 0 0" />
  </joint>
  <link
    name="arm_seg4">
    <inertial>
      <origin
        xyz="0.164195772878017 -0.000144257331110971 -0.00282861774678392"
        rpy="0 0 0" />
      <mass
        value="0.52965" />
      <inertia
        ixx="5.61524305952142E-05"
        ixy="2.20927624304882E-08"
        ixz="2.21109495236373E-07"
        iyy="0.000201483544507516"
        iyz="-1.14174511452196E-08"
        izz="0.000215217228329719" />
    </inertial>
    <visual>
      <origin
        xyz="0 0 0"
        rpy="0 0 0" />
      <geometry>
        <mesh
          filename="package://a1_arm_v3/meshes/arm_seg4.STL" />
      </geometry>
      <material
        name="">
        <color
          rgba="0.898039215686275 0.917647058823529 0.929411764705882 1" />
      </material>
    </visual>
    <collision>
      <origin
        xyz="0 0 0"
        rpy="0 0 0" />
      <geometry>
        <mesh
          filename="package://a1_arm_v3/meshes/arm_seg4.STL" />
      </geometry>
    </collision>
  </link>
  <joint
    name="arm_joint4"
    type="revolute">
    <limit effort="87" lower="-3.14" upper="3.14" velocity="2" />
    <origin
      xyz="-0.028342 -0.060749 0.07"
      rpy="-3.1416 0 -1.5708" />
    <parent
      link="arm_seg3" />
    <child
      link="arm_seg4" />
    <axis
      xyz="1 0 0" />
  </joint>
  <link
    name="arm_seg5">
    <inertial>
      <origin
        xyz="-0.013523043573808 -0.045272390264418 -0.00257409930457567"
        rpy="0 0 0" />
      <mass
        value="0.60055" />
      <inertia
        ixx="5.19121015639072E-05"
        ixy="3.87238896808265E-07"
        ixz="-6.54782717588787E-10"
        iyy="5.64197063102711E-05"
        iyz="4.80851622148796E-07"
        izz="4.75671436115134E-05" />
    </inertial>
    <visual>
      <origin
        xyz="0 0 0"
        rpy="0 0 0" />
      <geometry>
        <mesh
          filename="package://a1_arm_v3/meshes/arm_seg5.STL" />
      </geometry>
      <material
        name="">
        <color
          rgba="1 0.235294117647059 0.215686274509804 1" />
      </material>
    </visual>
    <collision>
      <origin
        xyz="0 0 0"
        rpy="0 0 0" />
      <geometry>
        <mesh
          filename="package://a1_arm_v3/meshes/arm_seg5.STL" />
      </geometry>
    </collision>
  </link>
  <joint
    name="arm_joint5"
    type="revolute">
    <limit effort="87" lower="-1.57" upper="1.57" velocity="2" />
    <origin
      xyz="0.2132 0 -0.02"
      rpy="-1.5708 1.5708 0" />
    <parent
      link="arm_seg4" />
    <child
      link="arm_seg5" />
    <axis
      xyz="1 0 0" />
  </joint>
  <link
      name="arm_seg6">
      <inertial>
        <origin
          xyz="0.023 -5.91070298915364E-05 0.0698233052867751"
          rpy="0 1.5708 0" />
        <mass
          value="0.57369602772606" />
        <inertia
          ixx="5.26233658899888E-05"
          ixy="-1.67191644321457E-07"
          ixz="-1.90985806143316E-13"
          iyy="5.28870073911995E-05"
          iyz="1.1420882588032E-08"
          izz="6.41349889047125E-05" />
      </inertial>
      <visual>
        <origin
          xyz="0.023 0 0"
          rpy="0 1.5708 0" />
        <geometry>
          <mesh
            filename="package://a1_arm_v3/meshes/arm_seg6.STL" />
        </geometry>
        <material
          name="">
          <color
            rgba="0.898039215686275 0.917647058823529 0.929411764705882 1" />
        </material>
      </visual>
      <collision>
        <origin
          xyz="0.023 0 0"
          rpy="0 1.5708 0" />
        <geometry>
          <mesh
            filename="package://a1_arm_v3/meshes/arm_seg6.STL" />
        </geometry>
      </collision>
    </link>
  <joint
    name="arm_joint6"
    type="revolute">
    <limit effort="87" lower="-3.14" upper="3.14" velocity="2" />
    <origin
      xyz="-0.02 -0.035945 -0.001993"
      rpy="-1.5708 0.055388 -1.5708" />
    <parent
      link="arm_seg5" />
    <child
      link="arm_seg6" />
    <axis
      xyz="-1 0 0" />
  </joint>
</robot>